Workbook

Sheet README
A1: DONEWELL INSURANCE — Methodist Branch Engagement Tracker
A2: Shared OneDrive workbook for all 13 branch managers to log Methodist Church / Health Facility engagements.
A4: PURPOSE
B5: Track every engagement between Donewell branch managers and Methodist Church dioceses, circuits, societies, and Methodist health facilities. The data feeds an automatic rollup dashboard that the Methodist Unit Manager uses to monitor field activity, pipeline progression and strategic KPI achievement.
A7: HOW TO USE — BRANCH MANAGERS
B8: 1. Open this file from the shared OneDrive folder (do NOT download). 2. Go to the 'Engagement Log' sheet. 3. Add one row per engagement. Use the dropdowns where provided — they auto-validate your entries. 4. Fill in pipeline value in GHS if a quotation was raised or expected. 5. Set a 'Next Action' and 'Next Action Date' so nothing slips. 6. Update 'Status' as the engagement progresses (Open → In Progress → Won/Lost/Closed). 7. Save the file — OneDrive auto-syncs. Other users see your updates within seconds.
A10: HOW TO USE — METHODIST UNIT MANAGER
B11: 1. Open the 'Dashboard' sheet for an at-a-glance rollup of engagement activity by branch, type and outcome. 2. Use the 'Branch Heatmap' to identify under-engaged branches. 3. The 'Calendar View' shows upcoming next-actions across all branches — your weekly review tool. 4. Update 'Annual Targets' on the Dashboard sheet to reflect the current year's strategic plan numbers. 5. Run monthly engagement reviews using the Dashboard as the anchor document.
A13: DATA ENTRY RULES
B14: • BLUE text = manager-entered fields · BLACK text = auto-calculated, do not type over. • Every engagement needs a Date, Branch, Institution and Engagement Type — others are encouraged but optional. • Use dropdowns to keep dashboards clean. Free-text entries break the rollup. • Pipeline Value is the EXPECTED annual premium in GHS if the policy converts. • Status 'Won' means a policy was actually issued — set Won Premium accordingly. • Never delete rows — set Status to 'Closed' to retire stale records.
A16: CONFLICT HANDLING
B17: If two managers edit at the same time, OneDrive co-authoring resolves it automatically. If you ever see a conflict warning, accept your changes and notify the Methodist Unit Manager.
A19: STRATEGIC ALIGNMENT
B20: This tracker supports Priority Area 1 of the 2026-2028 Strategic Plan (Build a Sustainable Methodist Business). Targets cascade from the strategic plan: 120/250/400 institutions profiled, 30/80/150 covered, 18/24/30 leadership engagements. Branch-level activity targets are set on the Dashboard sheet.
A22: SHEET GUIDE
B23: README — this page. Engagement Log — primary data entry. Dashboard — auto-rollup of activity, pipeline and progress vs targets. Branch Heatmap — branch-by-engagement-type matrix to spot gaps. Calendar View — upcoming next-actions sorted by date. Branches & Managers — directory of branches and assigned managers. Institutions Directory — list of all dioceses + health facilities for reference. Lookups — hidden dropdown source data (do not edit).

Sheet Engagement Log
A1: ENGAGEMENT LOG — All Branch Manager Field Activity
A2: One row per engagement. Use dropdowns. Save to sync via OneDrive.
A4: Total Engagements | B4: Open / In Progress | C4: Won | D4: Pipeline Value (GHS) | E4: Won Premium (GHS) | F4: Win Rate | G4: Engagements — This Month | H4: Overdue Next-Actions
A5: =COUNTA(B10:B509) -> 3 | B5: =COUNTIF(P10:P509,"Open")+COUNTIF(P10:P509,"In Progress") -> 1 | C5: =COUNTIF(P10:P509,"Won") -> 2 | D5: =SUMIFS(L10:L509,P10:P509,"<>Lost",P10:P509,"<>Closed") -> 430000 | E5: =SUMIFS(M10:M509,P10:P509,"Won") -> 320000 | F5: =IFERROR(COUNTIF(P10:P509,"Won")/(COUNTIF(P10:P509,"Won")+COUNTIF(P10:P509,"Lost")),0) -> 1 | G5: =SUMPRODUCT((MONTH(A10:A509)=MONTH(TODAY()))*(YEAR(A10:A509)=YEAR(TODAY()))*(A10:A509<>"")) -> 2 | H5: =SUMPRODUCT((O10:O509<TODAY())*(O10:O509<>"")*(P10:P509<>"Won")*(P10:P509<>"Lost")*(P10:P509<>"Closed")) -> 0
A9: Date | B9: Branch | C9: Manager Name | D9: Institution Name | E9: Institution Type | F9: Region/Diocese | G9: Engagement Type | H9: Contact Person | I9: Contact Role | J9: Contact Phone | K9: Outcome | L9: Pipeline Value (GHS) | M9: Won Premium (GHS) | N9: Next Action | O9: Next Action Date | P9: Status | Q9: Priority | R9: Notes
A10: =TODAY()-30 -> 46166 | B10: Accra Main | C10: [Branch Manager Name] | D10: Methodist Church Ghana — Accra Diocese | E10: Diocese HQ | F10: Accra | G10: Formal Meeting | H10: [Bishop's Office] | I10: Diocesan Bishop | J10: [Phone] | K10: Quotation Requested | L10: 250000 | M10: 0 | N10: Send fleet & property quotation | O10: =TODAY()-15 -> 46181 | P10: Won | Q10: High | R10: Initial introduction. Diocese requested fleet & property quotation for 4 vehicles and HQ building.
A11: =TODAY()-20 -> 46176 | B11: Kumasi | C11: [Branch Manager Name] | D11: Methodist Hospital Aburaso | E11: Health Facility | F11: Ashanti | G11: Presentation | H11: [Hospital Administrator] | I11: Administrator | J11: [Phone] | K11: Proposal Under Review | L11: 180000 | M11: 0 | N11: Follow up next week with revised premium | O11: =TODAY()+5 -> 46201 | P11: In Progress | Q11: High | R11: Presented professional indemnity + property cover. Admin reviewing with board.
A12: =TODAY()-10 -> 46186 | B12: Cape Coast | C12: [Branch Manager Name] | D12: Methodist Church Ghana — Cape Coast Diocese | E12: Diocese HQ | F12: Central | G12: Renewal Visit | H12: [Diocesan Secretary] | I12: Secretary | J12: [Phone] | K12: Won — Policy Issued | L12: 0 | M12: 320000 | N12: Schedule mid-term service review | O12: =TODAY()+90 -> 46286 | P12: Won | Q12: Medium | R12: Successful renewal — 3-year relationship continues.

Sheet Dashboard
A1: METHODIST ENGAGEMENT DASHBOARD — Rollup Across All 13 Branches
A2: Live aggregation from Engagement Log. Updated whenever a branch manager saves a change to OneDrive.
A4: ENGAGEMENTS YTD | D4: ACTIVE PIPELINE | G4: WON PREMIUM YTD | J4: WIN RATE | M4: OVERDUE NEXT-ACTIONS | P4: ACTIVE BRANCHES
A5: =COUNTIFS('Engagement Log'!A10:A509,">="&DATE(YEAR(TODAY()),1,1)) -> 3 | D5: =SUMIFS('Engagement Log'!L10:L509,'Engagement Log'!P10:P509,"<>Lost",'Engagement Log'!P10:P509,"<>Closed",'Engagement Log'!P10:P509,"<>Won") -> 180000 | G5: =SUMIFS('Engagement Log'!M10:M509,'Engagement Log'!P10:P509,"Won",'Engagement Log'!A10:A509,">="&DATE(YEAR(TODAY()),1,1)) -> 320000 | J5: =IFERROR(COUNTIF('Engagement Log'!P10:P509,"Won")/(COUNTIF('Engagement Log'!P10:P509,"Won")+COUNTIF('Engagement Log'!P10:P509,"Lost")),0) -> 1 | M5: =SUMPRODUCT(('Engagement Log'!O10:O509<TODAY())*('Engagement Log'!O10:O509<>"")*('Engagement Log'!P10:P509<>"Won")*('Engagement Log'!P10:P509<>"Lost")*('Engagement Log'!P10:P509<>"Closed")) -> 0 | P5: =SUMPRODUCT((COUNTIF('Engagement Log'!B10:B509,'Branches & Managers'!A4:A16)>0)*1) -> 3
A7: ="vs "&YEAR(TODAY())&" Target: "&TEXT(CHOOSE(MIN(MAX(YEAR(TODAY())-2025,1),3),$B$11,$C$11,$D$11),"#,##0") -> vs 2026 Target: 312 | D7: ="Open opportunities (GHS)" -> Open opportunities (GHS) | G7: ="Conversions this year" -> Conversions this year | J7: ="Won ÷ (Won+Lost)" -> Won ÷ (Won+Lost) | M7: ="Need immediate attention" -> Need immediate attention | P7: ="Out of 13 total" -> Out of 13 total
A9: ANNUAL TARGETS — Editable (aligned to Strategic Plan 2026-2028)
B10: 2026 | C10: 2027 | D10: 2028
A11: Total Branch Engagements (target) | B11: 312 | C11: 416 | D11: 520
A12: Leadership Engagements (Synod/Diocese) | B12: 18 | C12: 24 | D12: 30
A13: New Conversions (Won) | B13: 60 | C13: 100 | D13: 150
A14: Pipeline Value Target (GHS) | B14: 2000000 | C14: 5000000 | D14: 9000000
A16: ENGAGEMENT ROLLUP BY BRANCH
A17: Branch | B17: Total Eng. | C17: Won | D17: Lost | E17: Open/InProg | F17: Win Rate | G17: Pipeline (GHS) | H17: Won Premium (GHS) | I17: Last Engagement | J17: Days Since
A18: Accra Main | B18: =COUNTIF('Engagement Log'!B10:B509,$A18) -> 1 | C18: =COUNTIFS('Engagement Log'!B10:B509,$A18,'Engagement Log'!P10:P509,"Won") -> 1 | D18: =COUNTIFS('Engagement Log'!B10:B509,$A18,'Engagement Log'!P10:P509,"Lost") -> 0 | E18: =COUNTIFS('Engagement Log'!B10:B509,$A18,'Engagement Log'!P10:P509,"Open")+COUNTIFS('Engagement Log'!B10:B509,$A18,'Engagement Log'!P10:P509,"In Progress") -> 0 | F18: =IFERROR(C18/(C18+D18),0) -> 1 | G18: =SUMIFS('Engagement Log'!L10:L509,'Engagement Log'!B10:B509,$A18,'Engagement Log'!P10:P509,"<>Won",'Engagement Log'!P10:P509,"<>Lost",'Engagement Log'!P10:P509,"<>Closed") -> 0 | H18: =SUMIFS('Engagement Log'!M10:M509,'Engagement Log'!B10:B509,$A18,'Engagement Log'!P10:P509,"Won") -> 0 | I18: =IFERROR(maxifs('Engagement Log'!A10:A509,'Engagement Log'!B10:B509,$A18),"") | J18: =IFERROR(TODAY()-I18,"")
A19: Tema | B19: =COUNTIF('Engagement Log'!B10:B509,$A19) -> 0 | C19: =COUNTIFS('Engagement Log'!B10:B509,$A19,'Engagement Log'!P10:P509,"Won") -> 0 | D19: =COUNTIFS('Engagement Log'!B10:B509,$A19,'Engagement Log'!P10:P509,"Lost") -> 0 | E19: =COUNTIFS('Engagement Log'!B10:B509,$A19,'Engagement Log'!P10:P509,"Open")+COUNTIFS('Engagement Log'!B10:B509,$A19,'Engagement Log'!P10:P509,"In Progress") -> 0 | F19: =IFERROR(C19/(C19+D19),0) -> 0 | G19: =SUMIFS('Engagement Log'!L10:L509,'Engagement Log'!B10:B509,$A19,'Engagement Log'!P10:P509,"<>Won",'Engagement Log'!P10:P509,"<>Lost",'Engagement Log'!P10:P509,"<>Closed") -> 0 | H19: =SUMIFS('Engagement Log'!M10:M509,'Engagement Log'!B10:B509,$A19,'Engagement Log'!P10:P509,"Won") -> 0 | I19: =IFERROR(maxifs('Engagement Log'!A10:A509,'Engagement Log'!B10:B509,$A19),"") | J19: =IFERROR(TODAY()-I19,"")
A20: Kumasi | B20: =COUNTIF('Engagement Log'!B10:B509,$A20) -> 1 | C20: =COUNTIFS('Engagement Log'!B10:B509,$A20,'Engagement Log'!P10:P509,"Won") -> 0 | D20: =COUNTIFS('Engagement Log'!B10:B509,$A20,'Engagement Log'!P10:P509,"Lost") -> 0 | E20: =COUNTIFS('Engagement Log'!B10:B509,$A20,'Engagement Log'!P10:P509,"Open")+COUNTIFS('Engagement Log'!B10:B509,$A20,'Engagement Log'!P10:P509,"In Progress") -> 1 | F20: =IFERROR(C20/(C20+D20),0) -> 0 | G20: =SUMIFS('Engagement Log'!L10:L509,'Engagement Log'!B10:B509,$A20,'Engagement Log'!P10:P509,"<>Won",'Engagement Log'!P10:P509,"<>Lost",'Engagement Log'!P10:P509,"<>Closed") -> 180000 | H20: =SUMIFS('Engagement Log'!M10:M509,'Engagement Log'!B10:B509,$A20,'Engagement Log'!P10:P509,"Won") -> 0 | I20: =IFERROR(maxifs('Engagement Log'!A10:A509,'Engagement Log'!B10:B509,$A20),"") | J20: =IFERROR(TODAY()-I20,"")
A21: Obuasi | B21: =COUNTIF('Engagement Log'!B10:B509,$A21) -> 0 | C21: =COUNTIFS('Engagement Log'!B10:B509,$A21,'Engagement Log'!P10:P509,"Won") -> 0 | D21: =COUNTIFS('Engagement Log'!B10:B509,$A21,'Engagement Log'!P10:P509,"Lost") -> 0 | E21: =COUNTIFS('Engagement Log'!B10:B509,$A21,'Engagement Log'!P10:P509,"Open")+COUNTIFS('Engagement Log'!B10:B509,$A21,'Engagement Log'!P10:P509,"In Progress") -> 0 | F21: =IFERROR(C21/(C21+D21),0) -> 0 | G21: =SUMIFS('Engagement Log'!L10:L509,'Engagement Log'!B10:B509,$A21,'Engagement Log'!P10:P509,"<>Won",'Engagement Log'!P10:P509,"<>Lost",'Engagement Log'!P10:P509,"<>Closed") -> 0 | H21: =SUMIFS('Engagement Log'!M10:M509,'Engagement Log'!B10:B509,$A21,'Engagement Log'!P10:P509,"Won") -> 0 | I21: =IFERROR(maxifs('Engagement Log'!A10:A509,'Engagement Log'!B10:B509,$A21),"") | J21: =IFERROR(TODAY()-I21,"")
A22: Takoradi | B22: =COUNTIF('Engagement Log'!B10:B509,$A22) -> 0 | C22: =COUNTIFS('Engagement Log'!B10:B509,$A22,'Engagement Log'!P10:P509,"Won") -> 0 | D22: =COUNTIFS('Engagement Log'!B10:B509,$A22,'Engagement Log'!P10:P509,"Lost") -> 0 | E22: =COUNTIFS('Engagement Log'!B10:B509,$A22,'Engagement Log'!P10:P509,"Open")+COUNTIFS('Engagement Log'!B10:B509,$A22,'Engagement Log'!P10:P509,"In Progress") -> 0 | F22: =IFERROR(C22/(C22+D22),0) -> 0 | G22: =SUMIFS('Engagement Log'!L10:L509,'Engagement Log'!B10:B509,$A22,'Engagement Log'!P10:P509,"<>Won",'Engagement Log'!P10:P509,"<>Lost",'Engagement Log'!P10:P509,"<>Closed") -> 0 | H22: =SUMIFS('Engagement Log'!M10:M509,'Engagement Log'!B10:B509,$A22,'Engagement Log'!P10:P509,"Won") -> 0 | I22: =IFERROR(maxifs('Engagement Log'!A10:A509,'Engagement Log'!B10:B509,$A22),"") | J22: =IFERROR(TODAY()-I22,"")
A23: Tarkwa | B23: =COUNTIF('Engagement Log'!B10:B509,$A23) -> 0 | C23: =COUNTIFS('Engagement Log'!B10:B509,$A23,'Engagement Log'!P10:P509,"Won") -> 0 | D23: =COUNTIFS('Engagement Log'!B10:B509,$A23,'Engagement Log'!P10:P509,"Lost") -> 0 | E23: =COUNTIFS('Engagement Log'!B10:B509,$A23,'Engagement Log'!P10:P509,"Open")+COUNTIFS('Engagement Log'!B10:B509,$A23,'Engagement Log'!P10:P509,"In Progress") -> 0 | F23: =IFERROR(C23/(C23+D23),0) -> 0 | G23: =SUMIFS('Engagement Log'!L10:L509,'Engagement Log'!B10:B509,$A23,'Engagement Log'!P10:P509,"<>Won",'Engagement Log'!P10:P509,"<>Lost",'Engagement Log'!P10:P509,"<>Closed") -> 0 | H23: =SUMIFS('Engagement Log'!M10:M509,'Engagement Log'!B10:B509,$A23,'Engagement Log'!P10:P509,"Won") -> 0 | I23: =IFERROR(maxifs('Engagement Log'!A10:A509,'Engagement Log'!B10:B509,$A23),"") | J23: =IFERROR(TODAY()-I23,"")
A24: Cape Coast | B24: =COUNTIF('Engagement Log'!B10:B509,$A24) -> 1 | C24: =COUNTIFS('Engagement Log'!B10:B509,$A24,'Engagement Log'!P10:P509,"Won") -> 1 | D24: =COUNTIFS('Engagement Log'!B10:B509,$A24,'Engagement Log'!P10:P509,"Lost") -> 0 | E24: =COUNTIFS('Engagement Log'!B10:B509,$A24,'Engagement Log'!P10:P509,"Open")+COUNTIFS('Engagement Log'!B10:B509,$A24,'Engagement Log'!P10:P509,"In Progress") -> 0 | F24: =IFERROR(C24/(C24+D24),0) -> 1 | G24: =SUMIFS('Engagement Log'!L10:L509,'Engagement Log'!B10:B509,$A24,'Engagement Log'!P10:P509,"<>Won",'Engagement Log'!P10:P509,"<>Lost",'Engagement Log'!P10:P509,"<>Closed") -> 0 | H24: =SUMIFS('Engagement Log'!M10:M509,'Engagement Log'!B10:B509,$A24,'Engagement Log'!P10:P509,"Won") -> 320000 | I24: =IFERROR(maxifs('Engagement Log'!A10:A509,'Engagement Log'!B10:B509,$A24),"") | J24: =IFERROR(TODAY()-I24,"")
A25: Koforidua | B25: =COUNTIF('Engagement Log'!B10:B509,$A25) -> 0 | C25: =COUNTIFS('Engagement Log'!B10:B509,$A25,'Engagement Log'!P10:P509,"Won") -> 0 | D25: =COUNTIFS('Engagement Log'!B10:B509,$A25,'Engagement Log'!P10:P509,"Lost") -> 0 | E25: =COUNTIFS('Engagement Log'!B10:B509,$A25,'Engagement Log'!P10:P509,"Open")+COUNTIFS('Engagement Log'!B10:B509,$A25,'Engagement Log'!P10:P509,"In Progress") -> 0 | F25: =IFERROR(C25/(C25+D25),0) -> 0 | G25: =SUMIFS('Engagement Log'!L10:L509,'Engagement Log'!B10:B509,$A25,'Engagement Log'!P10:P509,"<>Won",'Engagement Log'!P10:P509,"<>Lost",'Engagement Log'!P10:P509,"<>Closed") -> 0 | H25: =SUMIFS('Engagement Log'!M10:M509,'Engagement Log'!B10:B509,$A25,'Engagement Log'!P10:P509,"Won") -> 0 | I25: =IFERROR(maxifs('Engagement Log'!A10:A509,'Engagement Log'!B10:B509,$A25),"") | J25: =IFERROR(TODAY()-I25,"")
A26: Sunyani | B26: =COUNTIF('Engagement Log'!B10:B509,$A26) -> 0 | C26: =COUNTIFS('Engagement Log'!B10:B509,$A26,'Engagement Log'!P10:P509,"Won") -> 0 | D26: =COUNTIFS('Engagement Log'!B10:B509,$A26,'Engagement Log'!P10:P509,"Lost") -> 0 | E26: =COUNTIFS('Engagement Log'!B10:B509,$A26,'Engagement Log'!P10:P509,"Open")+COUNTIFS('Engagement Log'!B10:B509,$A26,'Engagement Log'!P10:P509,"In Progress") -> 0 | F26: =IFERROR(C26/(C26+D26),0) -> 0 | G26: =SUMIFS('Engagement Log'!L10:L509,'Engagement Log'!B10:B509,$A26,'Engagement Log'!P10:P509,"<>Won",'Engagement Log'!P10:P509,"<>Lost",'Engagement Log'!P10:P509,"<>Closed") -> 0 | H26: =SUMIFS('Engagement Log'!M10:M509,'Engagement Log'!B10:B509,$A26,'Engagement Log'!P10:P509,"Won") -> 0 | I26: =IFERROR(maxifs('Engagement Log'!A10:A509,'Engagement Log'!B10:B509,$A26),"") | J26: =IFERROR(TODAY()-I26,"")
A27: Techiman | B27: =COUNTIF('Engagement Log'!B10:B509,$A27) -> 0 | C27: =COUNTIFS('Engagement Log'!B10:B509,$A27,'Engagement Log'!P10:P509,"Won") -> 0 | D27: =COUNTIFS('Engagement Log'!B10:B509,$A27,'Engagement Log'!P10:P509,"Lost") -> 0 | E27: =COUNTIFS('Engagement Log'!B10:B509,$A27,'Engagement Log'!P10:P509,"Open")+COUNTIFS('Engagement Log'!B10:B509,$A27,'Engagement Log'!P10:P509,"In Progress") -> 0 | F27: =IFERROR(C27/(C27+D27),0) -> 0 | G27: =SUMIFS('Engagement Log'!L10:L509,'Engagement Log'!B10:B509,$A27,'Engagement Log'!P10:P509,"<>Won",'Engagement Log'!P10:P509,"<>Lost",'Engagement Log'!P10:P509,"<>Closed") -> 0 | H27: =SUMIFS('Engagement Log'!M10:M509,'Engagement Log'!B10:B509,$A27,'Engagement Log'!P10:P509,"Won") -> 0 | I27: =IFERROR(maxifs('Engagement Log'!A10:A509,'Engagement Log'!B10:B509,$A27),"") | J27: =IFERROR(TODAY()-I27,"")
A28: Tamale | B28: =COUNTIF('Engagement Log'!B10:B509,$A28) -> 0 | C28: =COUNTIFS('Engagement Log'!B10:B509,$A28,'Engagement Log'!P10:P509,"Won") -> 0 | D28: =COUNTIFS('Engagement Log'!B10:B509,$A28,'Engagement Log'!P10:P509,"Lost") -> 0 | E28: =COUNTIFS('Engagement Log'!B10:B509,$A28,'Engagement Log'!P10:P509,"Open")+COUNTIFS('Engagement Log'!B10:B509,$A28,'Engagement Log'!P10:P509,"In Progress") -> 0 | F28: =IFERROR(C28/(C28+D28),0) -> 0 | G28: =SUMIFS('Engagement Log'!L10:L509,'Engagement Log'!B10:B509,$A28,'Engagement Log'!P10:P509,"<>Won",'Engagement Log'!P10:P509,"<>Lost",'Engagement Log'!P10:P509,"<>Closed") -> 0 | H28: =SUMIFS('Engagement Log'!M10:M509,'Engagement Log'!B10:B509,$A28,'Engagement Log'!P10:P509,"Won") -> 0 | I28: =IFERROR(maxifs('Engagement Log'!A10:A509,'Engagement Log'!B10:B509,$A28),"") | J28: =IFERROR(TODAY()-I28,"")
A29: Ho | B29: =COUNTIF('Engagement Log'!B10:B509,$A29) -> 0 | C29: =COUNTIFS('Engagement Log'!B10:B509,$A29,'Engagement Log'!P10:P509,"Won") -> 0 | D29: =COUNTIFS('Engagement Log'!B10:B509,$A29,'Engagement Log'!P10:P509,"Lost") -> 0 | E29: =COUNTIFS('Engagement Log'!B10:B509,$A29,'Engagement Log'!P10:P509,"Open")+COUNTIFS('Engagement Log'!B10:B509,$A29,'Engagement Log'!P10:P509,"In Progress") -> 0 | F29: =IFERROR(C29/(C29+D29),0) -> 0 | G29: =SUMIFS('Engagement Log'!L10:L509,'Engagement Log'!B10:B509,$A29,'Engagement Log'!P10:P509,"<>Won",'Engagement Log'!P10:P509,"<>Lost",'Engagement Log'!P10:P509,"<>Closed") -> 0 | H29: =SUMIFS('Engagement Log'!M10:M509,'Engagement Log'!B10:B509,$A29,'Engagement Log'!P10:P509,"Won") -> 0 | I29: =IFERROR(maxifs('Engagement Log'!A10:A509,'Engagement Log'!B10:B509,$A29),"") | J29: =IFERROR(TODAY()-I29,"")
A30: Wa | B30: =COUNTIF('Engagement Log'!B10:B509,$A30) -> 0 | C30: =COUNTIFS('Engagement Log'!B10:B509,$A30,'Engagement Log'!P10:P509,"Won") -> 0 | D30: =COUNTIFS('Engagement Log'!B10:B509,$A30,'Engagement Log'!P10:P509,"Lost") -> 0 | E30: =COUNTIFS('Engagement Log'!B10:B509,$A30,'Engagement Log'!P10:P509,"Open")+COUNTIFS('Engagement Log'!B10:B509,$A30,'Engagement Log'!P10:P509,"In Progress") -> 0 | F30: =IFERROR(C30/(C30+D30),0) -> 0 | G30: =SUMIFS('Engagement Log'!L10:L509,'Engagement Log'!B10:B509,$A30,'Engagement Log'!P10:P509,"<>Won",'Engagement Log'!P10:P509,"<>Lost",'Engagement Log'!P10:P509,"<>Closed") -> 0 | H30: =SUMIFS('Engagement Log'!M10:M509,'Engagement Log'!B10:B509,$A30,'Engagement Log'!P10:P509,"Won") -> 0 | I30: =IFERROR(maxifs('Engagement Log'!A10:A509,'Engagement Log'!B10:B509,$A30),"") | J30: =IFERROR(TODAY()-I30,"")
A31: TOTAL | B31: =SUM(B18:B30) -> 3 | C31: =SUM(C18:C30) -> 2 | D31: =SUM(D18:D30) -> 0 | E31: =SUM(E18:E30) -> 1 | F31: =IFERROR(C31/(C31+D31),0) -> 1 | G31: =SUM(G18:G30) -> 180000 | H31: =SUM(H18:H30) -> 320000
A34: BY ENGAGEMENT TYPE | H34: BY OUTCOME
A35: Engagement Type | B35: Count | C35: Pipeline (GHS) | D35: Won Premium (GHS) | H35: Outcome | I35: Count | J35: Pipeline (GHS)
A36: Courtesy Visit | B36: =COUNTIF('Engagement Log'!G10:G509,$A36) -> 0 | C36: =SUMIFS('Engagement Log'!L10:L509,'Engagement Log'!G10:G509,$A36) -> 0 | D36: =SUMIFS('Engagement Log'!M10:M509,'Engagement Log'!G10:G509,$A36,'Engagement Log'!P10:P509,"Won") -> 0 | H36: Prospect Identified | I36: =COUNTIF('Engagement Log'!K10:K509,$H36) -> 0 | J36: =SUMIFS('Engagement Log'!L10:L509,'Engagement Log'!K10:K509,$H36) -> 0
A37: Formal Meeting | B37: =COUNTIF('Engagement Log'!G10:G509,$A37) -> 1 | C37: =SUMIFS('Engagement Log'!L10:L509,'Engagement Log'!G10:G509,$A37) -> 250000 | D37: =SUMIFS('Engagement Log'!M10:M509,'Engagement Log'!G10:G509,$A37,'Engagement Log'!P10:P509,"Won") -> 0 | H37: Information Gathered | I37: =COUNTIF('Engagement Log'!K10:K509,$H37) -> 0 | J37: =SUMIFS('Engagement Log'!L10:L509,'Engagement Log'!K10:K509,$H37) -> 0
A38: Presentation | B38: =COUNTIF('Engagement Log'!G10:G509,$A38) -> 1 | C38: =SUMIFS('Engagement Log'!L10:L509,'Engagement Log'!G10:G509,$A38) -> 180000 | D38: =SUMIFS('Engagement Log'!M10:M509,'Engagement Log'!G10:G509,$A38,'Engagement Log'!P10:P509,"Won") -> 0 | H38: Quotation Requested | I38: =COUNTIF('Engagement Log'!K10:K509,$H38) -> 1 | J38: =SUMIFS('Engagement Log'!L10:L509,'Engagement Log'!K10:K509,$H38) -> 250000
A39: Quotation Discussion | B39: =COUNTIF('Engagement Log'!G10:G509,$A39) -> 0 | C39: =SUMIFS('Engagement Log'!L10:L509,'Engagement Log'!G10:G509,$A39) -> 0 | D39: =SUMIFS('Engagement Log'!M10:M509,'Engagement Log'!G10:G509,$A39,'Engagement Log'!P10:P509,"Won") -> 0 | H39: Quotation Sent | I39: =COUNTIF('Engagement Log'!K10:K509,$H39) -> 0 | J39: =SUMIFS('Engagement Log'!L10:L509,'Engagement Log'!K10:K509,$H39) -> 0
A40: Renewal Visit | B40: =COUNTIF('Engagement Log'!G10:G509,$A40) -> 1 | C40: =SUMIFS('Engagement Log'!L10:L509,'Engagement Log'!G10:G509,$A40) -> 0 | D40: =SUMIFS('Engagement Log'!M10:M509,'Engagement Log'!G10:G509,$A40,'Engagement Log'!P10:P509,"Won") -> 320000 | H40: Proposal Under Review | I40: =COUNTIF('Engagement Log'!K10:K509,$H40) -> 1 | J40: =SUMIFS('Engagement Log'!L10:L509,'Engagement Log'!K10:K509,$H40) -> 180000
A41: Claims Visit | B41: =COUNTIF('Engagement Log'!G10:G509,$A41) -> 0 | C41: =SUMIFS('Engagement Log'!L10:L509,'Engagement Log'!G10:G509,$A41) -> 0 | D41: =SUMIFS('Engagement Log'!M10:M509,'Engagement Log'!G10:G509,$A41,'Engagement Log'!P10:P509,"Won") -> 0 | H41: Won — Policy Issued | I41: =COUNTIF('Engagement Log'!K10:K509,$H41) -> 1 | J41: =SUMIFS('Engagement Log'!L10:L509,'Engagement Log'!K10:K509,$H41) -> 0
A42: Training/Workshop | B42: =COUNTIF('Engagement Log'!G10:G509,$A42) -> 0 | C42: =SUMIFS('Engagement Log'!L10:L509,'Engagement Log'!G10:G509,$A42) -> 0 | D42: =SUMIFS('Engagement Log'!M10:M509,'Engagement Log'!G10:G509,$A42,'Engagement Log'!P10:P509,"Won") -> 0 | H42: Lost — Price | I42: =COUNTIF('Engagement Log'!K10:K509,$H42) -> 0 | J42: =SUMIFS('Engagement Log'!L10:L509,'Engagement Log'!K10:K509,$H42) -> 0
A43: Synod Event | B43: =COUNTIF('Engagement Log'!G10:G509,$A43) -> 0 | C43: =SUMIFS('Engagement Log'!L10:L509,'Engagement Log'!G10:G509,$A43) -> 0 | D43: =SUMIFS('Engagement Log'!M10:M509,'Engagement Log'!G10:G509,$A43,'Engagement Log'!P10:P509,"Won") -> 0 | H43: Lost — Competitor | I43: =COUNTIF('Engagement Log'!K10:K509,$H43) -> 0 | J43: =SUMIFS('Engagement Log'!L10:L509,'Engagement Log'!K10:K509,$H43) -> 0
A44: Diocesan Event | B44: =COUNTIF('Engagement Log'!G10:G509,$A44) -> 0 | C44: =SUMIFS('Engagement Log'!L10:L509,'Engagement Log'!G10:G509,$A44) -> 0 | D44: =SUMIFS('Engagement Log'!M10:M509,'Engagement Log'!G10:G509,$A44,'Engagement Log'!P10:P509,"Won") -> 0 | H44: Lost — No Decision | I44: =COUNTIF('Engagement Log'!K10:K509,$H44) -> 0 | J44: =SUMIFS('Engagement Log'!L10:L509,'Engagement Log'!K10:K509,$H44) -> 0
A45: Society Visit | B45: =COUNTIF('Engagement Log'!G10:G509,$A45) -> 0 | C45: =SUMIFS('Engagement Log'!L10:L509,'Engagement Log'!G10:G509,$A45) -> 0 | D45: =SUMIFS('Engagement Log'!M10:M509,'Engagement Log'!G10:G509,$A45,'Engagement Log'!P10:P509,"Won") -> 0 | H45: Follow-up Required | I45: =COUNTIF('Engagement Log'!K10:K509,$H45) -> 0 | J45: =SUMIFS('Engagement Log'!L10:L509,'Engagement Log'!K10:K509,$H45) -> 0
A46: Cold Call | B46: =COUNTIF('Engagement Log'!G10:G509,$A46) -> 0 | C46: =SUMIFS('Engagement Log'!L10:L509,'Engagement Log'!G10:G509,$A46) -> 0 | D46: =SUMIFS('Engagement Log'!M10:M509,'Engagement Log'!G10:G509,$A46,'Engagement Log'!P10:P509,"Won") -> 0 | H46: Closed — No Interest | I46: =COUNTIF('Engagement Log'!K10:K509,$H46) -> 0 | J46: =SUMIFS('Engagement Log'!L10:L509,'Engagement Log'!K10:K509,$H46) -> 0
...

Sheet Branch Heatmap
A1: BRANCH × ENGAGEMENT-TYPE HEATMAP
A2: Identify branches with low or skewed engagement activity — colour scale highlights gaps.
A4: Branch | B4: Courtesy Visit | C4: Formal Meeting | D4: Presentation | E4: Quotation Discussion | F4: Renewal Visit | G4: Claims Visit | H4: Training/Workshop | I4: Synod Event | J4: Diocesan Event | K4: Society Visit | L4: Cold Call | M4: Phone Follow-up | N4: Email Follow-up | O4: Cross-sell Visit | P4: Service Recovery | Q4: TOTAL
A5: Accra Main | B5: =COUNTIFS('Engagement Log'!B10:B509,$A5,'Engagement Log'!G10:G509,B$4) -> 0 | C5: =COUNTIFS('Engagement Log'!B10:B509,$A5,'Engagement Log'!G10:G509,C$4) -> 1 | D5: =COUNTIFS('Engagement Log'!B10:B509,$A5,'Engagement Log'!G10:G509,D$4) -> 0 | E5: =COUNTIFS('Engagement Log'!B10:B509,$A5,'Engagement Log'!G10:G509,E$4) -> 0 | F5: =COUNTIFS('Engagement Log'!B10:B509,$A5,'Engagement Log'!G10:G509,F$4) -> 0 | G5: =COUNTIFS('Engagement Log'!B10:B509,$A5,'Engagement Log'!G10:G509,G$4) -> 0 | H5: =COUNTIFS('Engagement Log'!B10:B509,$A5,'Engagement Log'!G10:G509,H$4) -> 0 | I5: =COUNTIFS('Engagement Log'!B10:B509,$A5,'Engagement Log'!G10:G509,I$4) -> 0 | J5: =COUNTIFS('Engagement Log'!B10:B509,$A5,'Engagement Log'!G10:G509,J$4) -> 0 | K5: =COUNTIFS('Engagement Log'!B10:B509,$A5,'Engagement Log'!G10:G509,K$4) -> 0 | L5: =COUNTIFS('Engagement Log'!B10:B509,$A5,'Engagement Log'!G10:G509,L$4) -> 0 | M5: =COUNTIFS('Engagement Log'!B10:B509,$A5,'Engagement Log'!G10:G509,M$4) -> 0 | N5: =COUNTIFS('Engagement Log'!B10:B509,$A5,'Engagement Log'!G10:G509,N$4) -> 0 | O5: =COUNTIFS('Engagement Log'!B10:B509,$A5,'Engagement Log'!G10:G509,O$4) -> 0 | P5: =COUNTIFS('Engagement Log'!B10:B509,$A5,'Engagement Log'!G10:G509,P$4) -> 0 | Q5: =SUM(B5:P5) -> 1
A6: Tema | B6: =COUNTIFS('Engagement Log'!B10:B509,$A6,'Engagement Log'!G10:G509,B$4) -> 0 | C6: =COUNTIFS('Engagement Log'!B10:B509,$A6,'Engagement Log'!G10:G509,C$4) -> 0 | D6: =COUNTIFS('Engagement Log'!B10:B509,$A6,'Engagement Log'!G10:G509,D$4) -> 0 | E6: =COUNTIFS('Engagement Log'!B10:B509,$A6,'Engagement Log'!G10:G509,E$4) -> 0 | F6: =COUNTIFS('Engagement Log'!B10:B509,$A6,'Engagement Log'!G10:G509,F$4) -> 0 | G6: =COUNTIFS('Engagement Log'!B10:B509,$A6,'Engagement Log'!G10:G509,G$4) -> 0 | H6: =COUNTIFS('Engagement Log'!B10:B509,$A6,'Engagement Log'!G10:G509,H$4) -> 0 | I6: =COUNTIFS('Engagement Log'!B10:B509,$A6,'Engagement Log'!G10:G509,I$4) -> 0 | J6: =COUNTIFS('Engagement Log'!B10:B509,$A6,'Engagement Log'!G10:G509,J$4) -> 0 | K6: =COUNTIFS('Engagement Log'!B10:B509,$A6,'Engagement Log'!G10:G509,K$4) -> 0 | L6: =COUNTIFS('Engagement Log'!B10:B509,$A6,'Engagement Log'!G10:G509,L$4) -> 0 | M6: =COUNTIFS('Engagement Log'!B10:B509,$A6,'Engagement Log'!G10:G509,M$4) -> 0 | N6: =COUNTIFS('Engagement Log'!B10:B509,$A6,'Engagement Log'!G10:G509,N$4) -> 0 | O6: =COUNTIFS('Engagement Log'!B10:B509,$A6,'Engagement Log'!G10:G509,O$4) -> 0 | P6: =COUNTIFS('Engagement Log'!B10:B509,$A6,'Engagement Log'!G10:G509,P$4) -> 0 | Q6: =SUM(B6:P6) -> 0
A7: Kumasi | B7: =COUNTIFS('Engagement Log'!B10:B509,$A7,'Engagement Log'!G10:G509,B$4) -> 0 | C7: =COUNTIFS('Engagement Log'!B10:B509,$A7,'Engagement Log'!G10:G509,C$4) -> 0 | D7: =COUNTIFS('Engagement Log'!B10:B509,$A7,'Engagement Log'!G10:G509,D$4) -> 1 | E7: =COUNTIFS('Engagement Log'!B10:B509,$A7,'Engagement Log'!G10:G509,E$4) -> 0 | F7: =COUNTIFS('Engagement Log'!B10:B509,$A7,'Engagement Log'!G10:G509,F$4) -> 0 | G7: =COUNTIFS('Engagement Log'!B10:B509,$A7,'Engagement Log'!G10:G509,G$4) -> 0 | H7: =COUNTIFS('Engagement Log'!B10:B509,$A7,'Engagement Log'!G10:G509,H$4) -> 0 | I7: =COUNTIFS('Engagement Log'!B10:B509,$A7,'Engagement Log'!G10:G509,I$4) -> 0 | J7: =COUNTIFS('Engagement Log'!B10:B509,$A7,'Engagement Log'!G10:G509,J$4) -> 0 | K7: =COUNTIFS('Engagement Log'!B10:B509,$A7,'Engagement Log'!G10:G509,K$4) -> 0 | L7: =COUNTIFS('Engagement Log'!B10:B509,$A7,'Engagement Log'!G10:G509,L$4) -> 0 | M7: =COUNTIFS('Engagement Log'!B10:B509,$A7,'Engagement Log'!G10:G509,M$4) -> 0 | N7: =COUNTIFS('Engagement Log'!B10:B509,$A7,'Engagement Log'!G10:G509,N$4) -> 0 | O7: =COUNTIFS('Engagement Log'!B10:B509,$A7,'Engagement Log'!G10:G509,O$4) -> 0 | P7: =COUNTIFS('Engagement Log'!B10:B509,$A7,'Engagement Log'!G10:G509,P$4) -> 0 | Q7: =SUM(B7:P7) -> 1
A8: Obuasi | B8: =COUNTIFS('Engagement Log'!B10:B509,$A8,'Engagement Log'!G10:G509,B$4) -> 0 | C8: =COUNTIFS('Engagement Log'!B10:B509,$A8,'Engagement Log'!G10:G509,C$4) -> 0 | D8: =COUNTIFS('Engagement Log'!B10:B509,$A8,'Engagement Log'!G10:G509,D$4) -> 0 | E8: =COUNTIFS('Engagement Log'!B10:B509,$A8,'Engagement Log'!G10:G509,E$4) -> 0 | F8: =COUNTIFS('Engagement Log'!B10:B509,$A8,'Engagement Log'!G10:G509,F$4) -> 0 | G8: =COUNTIFS('Engagement Log'!B10:B509,$A8,'Engagement Log'!G10:G509,G$4) -> 0 | H8: =COUNTIFS('Engagement Log'!B10:B509,$A8,'Engagement Log'!G10:G509,H$4) -> 0 | I8: =COUNTIFS('Engagement Log'!B10:B509,$A8,'Engagement Log'!G10:G509,I$4) -> 0 | J8: =COUNTIFS('Engagement Log'!B10:B509,$A8,'Engagement Log'!G10:G509,J$4) -> 0 | K8: =COUNTIFS('Engagement Log'!B10:B509,$A8,'Engagement Log'!G10:G509,K$4) -> 0 | L8: =COUNTIFS('Engagement Log'!B10:B509,$A8,'Engagement Log'!G10:G509,L$4) -> 0 | M8: =COUNTIFS('Engagement Log'!B10:B509,$A8,'Engagement Log'!G10:G509,M$4) -> 0 | N8: =COUNTIFS('Engagement Log'!B10:B509,$A8,'Engagement Log'!G10:G509,N$4) -> 0 | O8: =COUNTIFS('Engagement Log'!B10:B509,$A8,'Engagement Log'!G10:G509,O$4) -> 0 | P8: =COUNTIFS('Engagement Log'!B10:B509,$A8,'Engagement Log'!G10:G509,P$4) -> 0 | Q8: =SUM(B8:P8) -> 0
A9: Takoradi | B9: =COUNTIFS('Engagement Log'!B10:B509,$A9,'Engagement Log'!G10:G509,B$4) -> 0 | C9: =COUNTIFS('Engagement Log'!B10:B509,$A9,'Engagement Log'!G10:G509,C$4) -> 0 | D9: =COUNTIFS('Engagement Log'!B10:B509,$A9,'Engagement Log'!G10:G509,D$4) -> 0 | E9: =COUNTIFS('Engagement Log'!B10:B509,$A9,'Engagement Log'!G10:G509,E$4) -> 0 | F9: =COUNTIFS('Engagement Log'!B10:B509,$A9,'Engagement Log'!G10:G509,F$4) -> 0 | G9: =COUNTIFS('Engagement Log'!B10:B509,$A9,'Engagement Log'!G10:G509,G$4) -> 0 | H9: =COUNTIFS('Engagement Log'!B10:B509,$A9,'Engagement Log'!G10:G509,H$4) -> 0 | I9: =COUNTIFS('Engagement Log'!B10:B509,$A9,'Engagement Log'!G10:G509,I$4) -> 0 | J9: =COUNTIFS('Engagement Log'!B10:B509,$A9,'Engagement Log'!G10:G509,J$4) -> 0 | K9: =COUNTIFS('Engagement Log'!B10:B509,$A9,'Engagement Log'!G10:G509,K$4) -> 0 | L9: =COUNTIFS('Engagement Log'!B10:B509,$A9,'Engagement Log'!G10:G509,L$4) -> 0 | M9: =COUNTIFS('Engagement Log'!B10:B509,$A9,'Engagement Log'!G10:G509,M$4) -> 0 | N9: =COUNTIFS('Engagement Log'!B10:B509,$A9,'Engagement Log'!G10:G509,N$4) -> 0 | O9: =COUNTIFS('Engagement Log'!B10:B509,$A9,'Engagement Log'!G10:G509,O$4) -> 0 | P9: =COUNTIFS('Engagement Log'!B10:B509,$A9,'Engagement Log'!G10:G509,P$4) -> 0 | Q9: =SUM(B9:P9) -> 0
A10: Tarkwa | B10: =COUNTIFS('Engagement Log'!B10:B509,$A10,'Engagement Log'!G10:G509,B$4) -> 0 | C10: =COUNTIFS('Engagement Log'!B10:B509,$A10,'Engagement Log'!G10:G509,C$4) -> 0 | D10: =COUNTIFS('Engagement Log'!B10:B509,$A10,'Engagement Log'!G10:G509,D$4) -> 0 | E10: =COUNTIFS('Engagement Log'!B10:B509,$A10,'Engagement Log'!G10:G509,E$4) -> 0 | F10: =COUNTIFS('Engagement Log'!B10:B509,$A10,'Engagement Log'!G10:G509,F$4) -> 0 | G10: =COUNTIFS('Engagement Log'!B10:B509,$A10,'Engagement Log'!G10:G509,G$4) -> 0 | H10: =COUNTIFS('Engagement Log'!B10:B509,$A10,'Engagement Log'!G10:G509,H$4) -> 0 | I10: =COUNTIFS('Engagement Log'!B10:B509,$A10,'Engagement Log'!G10:G509,I$4) -> 0 | J10: =COUNTIFS('Engagement Log'!B10:B509,$A10,'Engagement Log'!G10:G509,J$4) -> 0 | K10: =COUNTIFS('Engagement Log'!B10:B509,$A10,'Engagement Log'!G10:G509,K$4) -> 0 | L10: =COUNTIFS('Engagement Log'!B10:B509,$A10,'Engagement Log'!G10:G509,L$4) -> 0 | M10: =COUNTIFS('Engagement Log'!B10:B509,$A10,'Engagement Log'!G10:G509,M$4) -> 0 | N10: =COUNTIFS('Engagement Log'!B10:B509,$A10,'Engagement Log'!G10:G509,N$4) -> 0 | O10: =COUNTIFS('Engagement Log'!B10:B509,$A10,'Engagement Log'!G10:G509,O$4) -> 0 | P10: =COUNTIFS('Engagement Log'!B10:B509,$A10,'Engagement Log'!G10:G509,P$4) -> 0 | Q10: =SUM(B10:P10) -> 0
A11: Cape Coast | B11: =COUNTIFS('Engagement Log'!B10:B509,$A11,'Engagement Log'!G10:G509,B$4) -> 0 | C11: =COUNTIFS('Engagement Log'!B10:B509,$A11,'Engagement Log'!G10:G509,C$4) -> 0 | D11: =COUNTIFS('Engagement Log'!B10:B509,$A11,'Engagement Log'!G10:G509,D$4) -> 0 | E11: =COUNTIFS('Engagement Log'!B10:B509,$A11,'Engagement Log'!G10:G509,E$4) -> 0 | F11: =COUNTIFS('Engagement Log'!B10:B509,$A11,'Engagement Log'!G10:G509,F$4) -> 1 | G11: =COUNTIFS('Engagement Log'!B10:B509,$A11,'Engagement Log'!G10:G509,G$4) -> 0 | H11: =COUNTIFS('Engagement Log'!B10:B509,$A11,'Engagement Log'!G10:G509,H$4) -> 0 | I11: =COUNTIFS('Engagement Log'!B10:B509,$A11,'Engagement Log'!G10:G509,I$4) -> 0 | J11: =COUNTIFS('Engagement Log'!B10:B509,$A11,'Engagement Log'!G10:G509,J$4) -> 0 | K11: =COUNTIFS('Engagement Log'!B10:B509,$A11,'Engagement Log'!G10:G509,K$4) -> 0 | L11: =COUNTIFS('Engagement Log'!B10:B509,$A11,'Engagement Log'!G10:G509,L$4) -> 0 | M11: =COUNTIFS('Engagement Log'!B10:B509,$A11,'Engagement Log'!G10:G509,M$4) -> 0 | N11: =COUNTIFS('Engagement Log'!B10:B509,$A11,'Engagement Log'!G10:G509,N$4) -> 0 | O11: =COUNTIFS('Engagement Log'!B10:B509,$A11,'Engagement Log'!G10:G509,O$4) -> 0 | P11: =COUNTIFS('Engagement Log'!B10:B509,$A11,'Engagement Log'!G10:G509,P$4) -> 0 | Q11: =SUM(B11:P11) -> 1
A12: Koforidua | B12: =COUNTIFS('Engagement Log'!B10:B509,$A12,'Engagement Log'!G10:G509,B$4) -> 0 | C12: =COUNTIFS('Engagement Log'!B10:B509,$A12,'Engagement Log'!G10:G509,C$4) -> 0 | D12: =COUNTIFS('Engagement Log'!B10:B509,$A12,'Engagement Log'!G10:G509,D$4) -> 0 | E12: =COUNTIFS('Engagement Log'!B10:B509,$A12,'Engagement Log'!G10:G509,E$4) -> 0 | F12: =COUNTIFS('Engagement Log'!B10:B509,$A12,'Engagement Log'!G10:G509,F$4) -> 0 | G12: =COUNTIFS('Engagement Log'!B10:B509,$A12,'Engagement Log'!G10:G509,G$4) -> 0 | H12: =COUNTIFS('Engagement Log'!B10:B509,$A12,'Engagement Log'!G10:G509,H$4) -> 0 | I12: =COUNTIFS('Engagement Log'!B10:B509,$A12,'Engagement Log'!G10:G509,I$4) -> 0 | J12: =COUNTIFS('Engagement Log'!B10:B509,$A12,'Engagement Log'!G10:G509,J$4) -> 0 | K12: =COUNTIFS('Engagement Log'!B10:B509,$A12,'Engagement Log'!G10:G509,K$4) -> 0 | L12: =COUNTIFS('Engagement Log'!B10:B509,$A12,'Engagement Log'!G10:G509,L$4) -> 0 | M12: =COUNTIFS('Engagement Log'!B10:B509,$A12,'Engagement Log'!G10:G509,M$4) -> 0 | N12: =COUNTIFS('Engagement Log'!B10:B509,$A12,'Engagement Log'!G10:G509,N$4) -> 0 | O12: =COUNTIFS('Engagement Log'!B10:B509,$A12,'Engagement Log'!G10:G509,O$4) -> 0 | P12: =COUNTIFS('Engagement Log'!B10:B509,$A12,'Engagement Log'!G10:G509,P$4) -> 0 | Q12: =SUM(B12:P12) -> 0
A13: Sunyani | B13: =COUNTIFS('Engagement Log'!B10:B509,$A13,'Engagement Log'!G10:G509,B$4) -> 0 | C13: =COUNTIFS('Engagement Log'!B10:B509,$A13,'Engagement Log'!G10:G509,C$4) -> 0 | D13: =COUNTIFS('Engagement Log'!B10:B509,$A13,'Engagement Log'!G10:G509,D$4) -> 0 | E13: =COUNTIFS('Engagement Log'!B10:B509,$A13,'Engagement Log'!G10:G509,E$4) -> 0 | F13: =COUNTIFS('Engagement Log'!B10:B509,$A13,'Engagement Log'!G10:G509,F$4) -> 0 | G13: =COUNTIFS('Engagement Log'!B10:B509,$A13,'Engagement Log'!G10:G509,G$4) -> 0 | H13: =COUNTIFS('Engagement Log'!B10:B509,$A13,'Engagement Log'!G10:G509,H$4) -> 0 | I13: =COUNTIFS('Engagement Log'!B10:B509,$A13,'Engagement Log'!G10:G509,I$4) -> 0 | J13: =COUNTIFS('Engagement Log'!B10:B509,$A13,'Engagement Log'!G10:G509,J$4) -> 0 | K13: =COUNTIFS('Engagement Log'!B10:B509,$A13,'Engagement Log'!G10:G509,K$4) -> 0 | L13: =COUNTIFS('Engagement Log'!B10:B509,$A13,'Engagement Log'!G10:G509,L$4) -> 0 | M13: =COUNTIFS('Engagement Log'!B10:B509,$A13,'Engagement Log'!G10:G509,M$4) -> 0 | N13: =COUNTIFS('Engagement Log'!B10:B509,$A13,'Engagement Log'!G10:G509,N$4) -> 0 | O13: =COUNTIFS('Engagement Log'!B10:B509,$A13,'Engagement Log'!G10:G509,O$4) -> 0 | P13: =COUNTIFS('Engagement Log'!B10:B509,$A13,'Engagement Log'!G10:G509,P$4) -> 0 | Q13: =SUM(B13:P13) -> 0
A14: Techiman | B14: =COUNTIFS('Engagement Log'!B10:B509,$A14,'Engagement Log'!G10:G509,B$4) -> 0 | C14: =COUNTIFS('Engagement Log'!B10:B509,$A14,'Engagement Log'!G10:G509,C$4) -> 0 | D14: =COUNTIFS('Engagement Log'!B10:B509,$A14,'Engagement Log'!G10:G509,D$4) -> 0 | E14: =COUNTIFS('Engagement Log'!B10:B509,$A14,'Engagement Log'!G10:G509,E$4) -> 0 | F14: =COUNTIFS('Engagement Log'!B10:B509,$A14,'Engagement Log'!G10:G509,F$4) -> 0 | G14: =COUNTIFS('Engagement Log'!B10:B509,$A14,'Engagement Log'!G10:G509,G$4) -> 0 | H14: =COUNTIFS('Engagement Log'!B10:B509,$A14,'Engagement Log'!G10:G509,H$4) -> 0 | I14: =COUNTIFS('Engagement Log'!B10:B509,$A14,'Engagement Log'!G10:G509,I$4) -> 0 | J14: =COUNTIFS('Engagement Log'!B10:B509,$A14,'Engagement Log'!G10:G509,J$4) -> 0 | K14: =COUNTIFS('Engagement Log'!B10:B509,$A14,'Engagement Log'!G10:G509,K$4) -> 0 | L14: =COUNTIFS('Engagement Log'!B10:B509,$A14,'Engagement Log'!G10:G509,L$4) -> 0 | M14: =COUNTIFS('Engagement Log'!B10:B509,$A14,'Engagement Log'!G10:G509,M$4) -> 0 | N14: =COUNTIFS('Engagement Log'!B10:B509,$A14,'Engagement Log'!G10:G509,N$4) -> 0 | O14: =COUNTIFS('Engagement Log'!B10:B509,$A14,'Engagement Log'!G10:G509,O$4) -> 0 | P14: =COUNTIFS('Engagement Log'!B10:B509,$A14,'Engagement Log'!G10:G509,P$4) -> 0 | Q14: =SUM(B14:P14) -> 0
A15: Tamale | B15: =COUNTIFS('Engagement Log'!B10:B509,$A15,'Engagement Log'!G10:G509,B$4) -> 0 | C15: =COUNTIFS('Engagement Log'!B10:B509,$A15,'Engagement Log'!G10:G509,C$4) -> 0 | D15: =COUNTIFS('Engagement Log'!B10:B509,$A15,'Engagement Log'!G10:G509,D$4) -> 0 | E15: =COUNTIFS('Engagement Log'!B10:B509,$A15,'Engagement Log'!G10:G509,E$4) -> 0 | F15: =COUNTIFS('Engagement Log'!B10:B509,$A15,'Engagement Log'!G10:G509,F$4) -> 0 | G15: =COUNTIFS('Engagement Log'!B10:B509,$A15,'Engagement Log'!G10:G509,G$4) -> 0 | H15: =COUNTIFS('Engagement Log'!B10:B509,$A15,'Engagement Log'!G10:G509,H$4) -> 0 | I15: =COUNTIFS('Engagement Log'!B10:B509,$A15,'Engagement Log'!G10:G509,I$4) -> 0 | J15: =COUNTIFS('Engagement Log'!B10:B509,$A15,'Engagement Log'!G10:G509,J$4) -> 0 | K15: =COUNTIFS('Engagement Log'!B10:B509,$A15,'Engagement Log'!G10:G509,K$4) -> 0 | L15: =COUNTIFS('Engagement Log'!B10:B509,$A15,'Engagement Log'!G10:G509,L$4) -> 0 | M15: =COUNTIFS('Engagement Log'!B10:B509,$A15,'Engagement Log'!G10:G509,M$4) -> 0 | N15: =COUNTIFS('Engagement Log'!B10:B509,$A15,'Engagement Log'!G10:G509,N$4) -> 0 | O15: =COUNTIFS('Engagement Log'!B10:B509,$A15,'Engagement Log'!G10:G509,O$4) -> 0 | P15: =COUNTIFS('Engagement Log'!B10:B509,$A15,'Engagement Log'!G10:G509,P$4) -> 0 | Q15: =SUM(B15:P15) -> 0
A16: Ho | B16: =COUNTIFS('Engagement Log'!B10:B509,$A16,'Engagement Log'!G10:G509,B$4) -> 0 | C16: =COUNTIFS('Engagement Log'!B10:B509,$A16,'Engagement Log'!G10:G509,C$4) -> 0 | D16: =COUNTIFS('Engagement Log'!B10:B509,$A16,'Engagement Log'!G10:G509,D$4) -> 0 | E16: =COUNTIFS('Engagement Log'!B10:B509,$A16,'Engagement Log'!G10:G509,E$4) -> 0 | F16: =COUNTIFS('Engagement Log'!B10:B509,$A16,'Engagement Log'!G10:G509,F$4) -> 0 | G16: =COUNTIFS('Engagement Log'!B10:B509,$A16,'Engagement Log'!G10:G509,G$4) -> 0 | H16: =COUNTIFS('Engagement Log'!B10:B509,$A16,'Engagement Log'!G10:G509,H$4) -> 0 | I16: =COUNTIFS('Engagement Log'!B10:B509,$A16,'Engagement Log'!G10:G509,I$4) -> 0 | J16: =COUNTIFS('Engagement Log'!B10:B509,$A16,'Engagement Log'!G10:G509,J$4) -> 0 | K16: =COUNTIFS('Engagement Log'!B10:B509,$A16,'Engagement Log'!G10:G509,K$4) -> 0 | L16: =COUNTIFS('Engagement Log'!B10:B509,$A16,'Engagement Log'!G10:G509,L$4) -> 0 | M16: =COUNTIFS('Engagement Log'!B10:B509,$A16,'Engagement Log'!G10:G509,M$4) -> 0 | N16: =COUNTIFS('Engagement Log'!B10:B509,$A16,'Engagement Log'!G10:G509,N$4) -> 0 | O16: =COUNTIFS('Engagement Log'!B10:B509,$A16,'Engagement Log'!G10:G509,O$4) -> 0 | P16: =COUNTIFS('Engagement Log'!B10:B509,$A16,'Engagement Log'!G10:G509,P$4) -> 0 | Q16: =SUM(B16:P16) -> 0
A17: Wa | B17: =COUNTIFS('Engagement Log'!B10:B509,$A17,'Engagement Log'!G10:G509,B$4) -> 0 | C17: =COUNTIFS('Engagement Log'!B10:B509,$A17,'Engagement Log'!G10:G509,C$4) -> 0 | D17: =COUNTIFS('Engagement Log'!B10:B509,$A17,'Engagement Log'!G10:G509,D$4) -> 0 | E17: =COUNTIFS('Engagement Log'!B10:B509,$A17,'Engagement Log'!G10:G509,E$4) -> 0 | F17: =COUNTIFS('Engagement Log'!B10:B509,$A17,'Engagement Log'!G10:G509,F$4) -> 0 | G17: =COUNTIFS('Engagement Log'!B10:B509,$A17,'Engagement Log'!G10:G509,G$4) -> 0 | H17: =COUNTIFS('Engagement Log'!B10:B509,$A17,'Engagement Log'!G10:G509,H$4) -> 0 | I17: =COUNTIFS('Engagement Log'!B10:B509,$A17,'Engagement Log'!G10:G509,I$4) -> 0 | J17: =COUNTIFS('Engagement Log'!B10:B509,$A17,'Engagement Log'!G10:G509,J$4) -> 0 | K17: =COUNTIFS('Engagement Log'!B10:B509,$A17,'Engagement Log'!G10:G509,K$4) -> 0 | L17: =COUNTIFS('Engagement Log'!B10:B509,$A17,'Engagement Log'!G10:G509,L$4) -> 0 | M17: =COUNTIFS('Engagement Log'!B10:B509,$A17,'Engagement Log'!G10:G509,M$4) -> 0 | N17: =COUNTIFS('Engagement Log'!B10:B509,$A17,'Engagement Log'!G10:G509,N$4) -> 0 | O17: =COUNTIFS('Engagement Log'!B10:B509,$A17,'Engagement Log'!G10:G509,O$4) -> 0 | P17: =COUNTIFS('Engagement Log'!B10:B509,$A17,'Engagement Log'!G10:G509,P$4) -> 0 | Q17: =SUM(B17:P17) -> 0
A18: TOTAL | B18: =SUM(B5:B17) -> 0 | C18: =SUM(C5:C17) -> 1 | D18: =SUM(D5:D17) -> 1 | E18: =SUM(E5:E17) -> 0 | F18: =SUM(F5:F17) -> 1 | G18: =SUM(G5:G17) -> 0 | H18: =SUM(H5:H17) -> 0 | I18: =SUM(I5:I17) -> 0 | ... Q18: =SUM(Q5:Q17) -> 3

Sheet Calendar View
A1: CALENDAR VIEW — Upcoming Next-Actions
A2: Open this each Monday morning. Filter by branch or sort by date.
A4: Next Action Date | B4: Days Until | C4: Branch | D4: Institution | E4: Engagement Type | F4: Next Action | G4: Manager | H4: Status | I4: Priority | J4: Pipeline (GHS)
A5: =IF('Engagement Log'!O10="","",'Engagement Log'!O10) -> 46181 | B5: =IF('Engagement Log'!O10="","",'Engagement Log'!O10-TODAY()) -> -15 | C5: =IF('Engagement Log'!B10="","",'Engagement Log'!B10) -> Accra Main | D5: =IF('Engagement Log'!D10="","",'Engagement Log'!D10) -> Methodist Church Ghana — Accra Diocese | E5: =IF('Engagement Log'!G10="","",'Engagement Log'!G10) -> Formal Meeting | F5: =IF('Engagement Log'!N10="","",'Engagement Log'!N10) -> Send fleet & property quotation | G5: =IF('Engagement Log'!C10="","",'Engagement Log'!C10) -> [Branch Manager Name] | H5: =IF('Engagement Log'!P10="","",'Engagement Log'!P10) -> Won | I5: =IF('Engagement Log'!Q10="","",'Engagement Log'!Q10) -> High | J5: =IF('Engagement Log'!L10="","",'Engagement Log'!L10) -> 250000
A6: =IF('Engagement Log'!O11="","",'Engagement Log'!O11) -> 46201 | B6: =IF('Engagement Log'!O11="","",'Engagement Log'!O11-TODAY()) -> 5 | C6: =IF('Engagement Log'!B11="","",'Engagement Log'!B11) -> Kumasi | D6: =IF('Engagement Log'!D11="","",'Engagement Log'!D11) -> Methodist Hospital Aburaso | E6: =IF('Engagement Log'!G11="","",'Engagement Log'!G11) -> Presentation | F6: =IF('Engagement Log'!N11="","",'Engagement Log'!N11) -> Follow up next week with revised premium | G6: =IF('Engagement Log'!C11="","",'Engagement Log'!C11) -> [Branch Manager Name] | H6: =IF('Engagement Log'!P11="","",'Engagement Log'!P11) -> In Progress | I6: =IF('Engagement Log'!Q11="","",'Engagement Log'!Q11) -> High | J6: =IF('Engagement Log'!L11="","",'Engagement Log'!L11) -> 180000
A7: =IF('Engagement Log'!O12="","",'Engagement Log'!O12) -> 46286 | B7: =IF('Engagement Log'!O12="","",'Engagement Log'!O12-TODAY()) -> 90 | C7: =IF('Engagement Log'!B12="","",'Engagement Log'!B12) -> Cape Coast | D7: =IF('Engagement Log'!D12="","",'Engagement Log'!D12) -> Methodist Church Ghana — Cape Coast Diocese | E7: =IF('Engagement Log'!G12="","",'Engagement Log'!G12) -> Renewal Visit | F7: =IF('Engagement Log'!N12="","",'Engagement Log'!N12) -> Schedule mid-term service review | G7: =IF('Engagement Log'!C12="","",'Engagement Log'!C12) -> [Branch Manager Name] | H7: =IF('Engagement Log'!P12="","",'Engagement Log'!P12) -> Won | I7: =IF('Engagement Log'!Q12="","",'Engagement Log'!Q12) -> Medium | J7: =IF('Engagement Log'!L12="","",'Engagement Log'!L12) -> 0
A8: =IF('Engagement Log'!O13="","",'Engagement Log'!O13) | B8: =IF('Engagement Log'!O13="","",'Engagement Log'!O13-TODAY()) | C8: =IF('Engagement Log'!B13="","",'Engagement Log'!B13) | D8: =IF('Engagement Log'!D13="","",'Engagement Log'!D13) | E8: =IF('Engagement Log'!G13="","",'Engagement Log'!G13) | F8: =IF('Engagement Log'!N13="","",'Engagement Log'!N13) | G8: =IF('Engagement Log'!C13="","",'Engagement Log'!C13) | H8: =IF('Engagement Log'!P13="","",'Engagement Log'!P13) | I8: =IF('Engagement Log'!Q13="","",'Engagement Log'!Q13) | J8: =IF('Engagement Log'!L13="","",'Engagement Log'!L13)
A9: =IF('Engagement Log'!O14="","",'Engagement Log'!O14) | B9: =IF('Engagement Log'!O14="","",'Engagement Log'!O14-TODAY()) | C9: =IF('Engagement Log'!B14="","",'Engagement Log'!B14) | D9: =IF('Engagement Log'!D14="","",'Engagement Log'!D14) | E9: =IF('Engagement Log'!G14="","",'Engagement Log'!G14) | F9: =IF('Engagement Log'!N14="","",'Engagement Log'!N14) | G9: =IF('Engagement Log'!C14="","",'Engagement Log'!C14) | H9: =IF('Engagement Log'!P14="","",'Engagement Log'!P14) | I9: =IF('Engagement Log'!Q14="","",'Engagement Log'!Q14) | J9: =IF('Engagement Log'!L14="","",'Engagement Log'!L14)
A10: =IF('Engagement Log'!O15="","",'Engagement Log'!O15) | B10: =IF('Engagement Log'!O15="","",'Engagement Log'!O15-TODAY()) | C10: =IF('Engagement Log'!B15="","",'Engagement Log'!B15) | D10: =IF('Engagement Log'!D15="","",'Engagement Log'!D15) | E10: =IF('Engagement Log'!G15="","",'Engagement Log'!G15) | F10: =IF('Engagement Log'!N15="","",'Engagement Log'!N15) | G10: =IF('Engagement Log'!C15="","",'Engagement Log'!C15) | H10: =IF('Engagement Log'!P15="","",'Engagement Log'!P15) | I10: =IF('Engagement Log'!Q15="","",'Engagement Log'!Q15) | J10: =IF('Engagement Log'!L15="","",'Engagement Log'!L15)
A11: =IF('Engagement Log'!O16="","",'Engagement Log'!O16) | B11: =IF('Engagement Log'!O16="","",'Engagement Log'!O16-TODAY()) | C11: =IF('Engagement Log'!B16="","",'Engagement Log'!B16) | D11: =IF('Engagement Log'!D16="","",'Engagement Log'!D16) | E11: =IF('Engagement Log'!G16="","",'Engagement Log'!G16) | F11: =IF('Engagement Log'!N16="","",'Engagement Log'!N16) | G11: =IF('Engagement Log'!C16="","",'Engagement Log'!C16) | H11: =IF('Engagement Log'!P16="","",'Engagement Log'!P16) | I11: =IF('Engagement Log'!Q16="","",'Engagement Log'!Q16) | J11: =IF('Engagement Log'!L16="","",'Engagement Log'!L16)
A12: =IF('Engagement Log'!O17="","",'Engagement Log'!O17) | B12: =IF('Engagement Log'!O17="","",'Engagement Log'!O17-TODAY()) | C12: =IF('Engagement Log'!B17="","",'Engagement Log'!B17) | D12: =IF('Engagement Log'!D17="","",'Engagement Log'!D17) | E12: =IF('Engagement Log'!G17="","",'Engagement Log'!G17) | F12: =IF('Engagement Log'!N17="","",'Engagement Log'!N17) | G12: =IF('Engagement Log'!C17="","",'Engagement Log'!C17) | H12: =IF('Engagement Log'!P17="","",'Engagement Log'!P17) | I12: =IF('Engagement Log'!Q17="","",'Engagement Log'!Q17) | J12: =IF('Engagement Log'!L17="","",'Engagement Log'!L17)
A13: =IF('Engagement Log'!O18="","",'Engagement Log'!O18) | B13: =IF('Engagement Log'!O18="","",'Engagement Log'!O18-TODAY()) | C13: =IF('Engagement Log'!B18="","",'Engagement Log'!B18) | D13: =IF('Engagement Log'!D18="","",'Engagement Log'!D18) | E13: =IF('Engagement Log'!G18="","",'Engagement Log'!G18) | F13: =IF('Engagement Log'!N18="","",'Engagement Log'!N18) | G13: =IF('Engagement Log'!C18="","",'Engagement Log'!C18) | H13: =IF('Engagement Log'!P18="","",'Engagement Log'!P18) | I13: =IF('Engagement Log'!Q18="","",'Engagement Log'!Q18) | J13: =IF('Engagement Log'!L18="","",'Engagement Log'!L18)
A14: =IF('Engagement Log'!O19="","",'Engagement Log'!O19) | B14: =IF('Engagement Log'!O19="","",'Engagement Log'!O19-TODAY()) | C14: =IF('Engagement Log'!B19="","",'Engagement Log'!B19) | D14: =IF('Engagement Log'!D19="","",'Engagement Log'!D19) | E14: =IF('Engagement Log'!G19="","",'Engagement Log'!G19) | F14: =IF('Engagement Log'!N19="","",'Engagement Log'!N19) | G14: =IF('Engagement Log'!C19="","",'Engagement Log'!C19) | H14: =IF('Engagement Log'!P19="","",'Engagement Log'!P19) | I14: =IF('Engagement Log'!Q19="","",'Engagement Log'!Q19) | J14: =IF('Engagement Log'!L19="","",'Engagement Log'!L19)
A15: =IF('Engagement Log'!O20="","",'Engagement Log'!O20) | B15: =IF('Engagement Log'!O20="","",'Engagement Log'!O20-TODAY()) | C15: =IF('Engagement Log'!B20="","",'Engagement Log'!B20) | D15: =IF('Engagement Log'!D20="","",'Engagement Log'!D20) | E15: =IF('Engagement Log'!G20="","",'Engagement Log'!G20) | F15: =IF('Engagement Log'!N20="","",'Engagement Log'!N20) | G15: =IF('Engagement Log'!C20="","",'Engagement Log'!C20) | H15: =IF('Engagement Log'!P20="","",'Engagement Log'!P20) | I15: =IF('Engagement Log'!Q20="","",'Engagement Log'!Q20) | J15: =IF('Engagement Log'!L20="","",'Engagement Log'!L20)
A16: =IF('Engagement Log'!O21="","",'Engagement Log'!O21) | B16: =IF('Engagement Log'!O21="","",'Engagement Log'!O21-TODAY()) | C16: =IF('Engagement Log'!B21="","",'Engagement Log'!B21) | D16: =IF('Engagement Log'!D21="","",'Engagement Log'!D21) | E16: =IF('Engagement Log'!G21="","",'Engagement Log'!G21) | F16: =IF('Engagement Log'!N21="","",'Engagement Log'!N21) | G16: =IF('Engagement Log'!C21="","",'Engagement Log'!C21) | H16: =IF('Engagement Log'!P21="","",'Engagement Log'!P21) | I16: =IF('Engagement Log'!Q21="","",'Engagement Log'!Q21) | J16: =IF('Engagement Log'!L21="","",'Engagement Log'!L21)
... A504: =IF('Engagement Log'!O509="","",'Engagement Log'!O509) | B504: =IF('Engagement Log'!O509="","",'Engagement Log'!O509-TODAY()) | C504: =IF('Engagement Log'!B509="","",'Engagement Log'!B509) | D504: =IF('Engagement Log'!D509="","",'Engagement Log'!D509) | E504: =IF('Engagement Log'!G509="","",'Engagement Log'!G509) | F504: =IF('Engagement Log'!N509="","",'Engagement Log'!N509) | G504: =IF('Engagement Log'!C509="","",'Engagement Log'!C509) | H504: =IF('Engagement Log'!P509="","",'Engagement Log'!P509) | I504: =IF('Engagement Log'!Q509="","",'Engagement Log'!Q509) | J504: =IF('Engagement Log'!L509="","",'Engagement Log'!L509)

Sheet Branches & Managers
A1: BRANCHES & ASSIGNED MANAGERS
A2: Edit manager names and contact details to keep this list current.
A3: Branch | B3: Region | C3: Branch Manager | D3: Email | E3: Phone
A4: Accra Main | B4: Greater Accra | C4: Ernest Kwasi Hammond | D4: ekhammond@donewellinsurance.com | E4: 546476270
A5: Tema | B5: Greater Accra | C5: Yvette Selinam Xetsa Ampofo | D5: ysxampofo@donewellinsurance.com | E5: 243352915
A6: Kumasi | B6: Ashanti | C6: Samuel Lartey | D6: slartey@donewellinsurance.com | E6: 501603895
A7: Obuasi | B7: Ashanti | C7: Samuel Lartey | D7: slartey@donewellinsurance.com | E7: 501603895
A8: Takoradi | B8: Western | C8: Anthony Borlu | D8: aborlu@donewellinsurance.com | E8: 242738958
A9: Tarkwa | B9: Western | C9: Anthony Borlu | D9: aborlu@donewellinsurance.com | E9: 242738958
A10: Cape Coast | B10: Central | C10: John Blankson | D10: jblankson@donewellinsurance.com | E10: 202077003
A11: Koforidua | B11: Eastern | C11: Cyril Tetteh | D11: ctetteh@donewellinsurance.com | E11: 244134464
A12: Sunyani | B12: Bono | C12: Patrick Donkoh | D12: pdonkoh@donewellinsurance.com | E12: 501603896
A13: Techiman | B13: Bono East | C13: Patrick Donkoh | D13: pdonkoh@donewellinsurance.com | E13: 501603896
A14: Tamale | B14: Northern | C14: Benjamin Lorwont Ninlabsiba | D14: blninlabsiba@donewellinsurance.com | E14: 247833524
A15: Ho | B15: Volta | C15: Korleki Setor Akpey | D15: ksakpey@donewellinsurance.com | E15: 507307811
A16: Wa | B16: Upper West | C16: Benjamin Lorwont Ninlabsiba | D16: blninlabsiba@donewellinsurance.com | E16: 247833524

Sheet Institutions Directory
A1: METHODIST INSTITUTIONS DIRECTORY — 21 Dioceses + 26 Health Facilities
A2: Reference list. The Engagement Log dropdown pulls from this sheet (via Lookups).
A4: Institution Name | B4: Type | C4: Region | D4: Assigned Branch | E4: Circuits / Notes | F4: Membership
A5: Methodist Church Ghana — Cape Coast Diocese | B5: Diocese | C5: Central | D5: Cape Coast | E5: 34 circuits, 256 societies | F5: 38187
A6: Methodist Church Ghana — Accra Diocese | B6: Diocese | C6: Greater Accra | D6: Accra Main | E6: 24 circuits, 106 societies | F6: 35229
A7: Methodist Church Ghana — Kumasi Diocese | B7: Diocese | C7: Ashanti | D7: Kumasi | E7: 40 circuits, 550 societies | F7: 85636
A8: Methodist Church Ghana — Sekondi Diocese | B8: Diocese | C8: Western | D8: Takoradi | E8: 18 circuits, 347 societies | F8: 59091
A9: Methodist Church Ghana — Winneba Diocese | B9: Diocese | C9: Central | D9: Cape Coast | E9: 21 circuits, 355 societies | F9: 47037
A10: Methodist Church Ghana — Koforidua Diocese | B10: Diocese | C10: Eastern | D10: Koforidua | E10: 20 circuits, 168 societies | F10: 19473
A11: Methodist Church Ghana — Sunyani Diocese | B11: Diocese | C11: Bono | D11: Sunyani | E11: 16 circuits, 260 societies | F11: 31134
A12: Methodist Church Ghana — Tarkwa Diocese | B12: Diocese | C12: Western | D12: Tarkwa | E12: 16 circuits, 363 societies | F12: 39195
A13: Methodist Church Ghana — Tamale Diocese | B13: Diocese | C13: Northern | D13: Tamale | E13: 10 circuits, 51 societies | F13: 3528
A14: Methodist Church Ghana — Oda Diocese | B14: Diocese | C14: Eastern | D14: Koforidua | E14: 17 circuits, 194 societies | F14: 18474
A15: Methodist Church Ghana — Effiduase Diocese | B15: Diocese | C15: Ashanti | D15: Kumasi | E15: 18 circuits, 267 societies | F15: 30288
A16: Methodist Church Ghana — Obuasi Diocese | B16: Diocese | C16: Ashanti | D16: Obuasi | E16: 21 circuits, 256 societies | F16: 23803
... A25: Methodist Church Ghana — Ho Diocese | B25: Diocese | C25: Volta | D25: Ho | E25: 6 circuits, 66 societies | F25: 4826
A26: Methodist Health Training Institute Afosu Campus | B26: Health Facility | C26: Eastern | D26: Koforidua | E26: New Abirem · 0244280748
A27: Methodist Medical Centre Lawra | B27: Health Facility | C27: Upper East | D27: Tamale | E27: Northern Ghana · 0203190696
A28: Methodist Medical Centre Yipala | B28: Health Facility | C28: Northern Ghana | D28: Tamale | E28: Zangey Yipala · 0248783205
A29: Methodist Hospital Wenchi | B29: Health Facility | C29: Bono East | D29: Techiman | E29: Wenchi · 0208181340
A30: Methodist Medical Centre Kwakuyanya | B30: Health Facility | C30: Bono Region | D30: Sunyani | E30: Kwakuyanya · 0241645002
A31: Methodist Medical Centre Yawase | B31: Health Facility | C31: Brong Ahafo | D31: Sunyani | E31: Yawase · 0241645003
A32: Methodist Medical Centre Asuakwa | B32: Health Facility | C32: Ashanti Region | D32: Kumasi | E32: Asuakwa · 0241645004
A33: Methodist Medical Centre Adagyaman | B33: Health Facility | C33: Ahafo Region | D33: Sunyani | E33: Adagyaman · 0241645005
A34: Methodist Medical Centre Apagya | B34: Health Facility | C34: Ashanti Region | D34: Kumasi | E34: Apagya · 0247844820
A35: Methodist Medical Centre Adum | B35: Health Facility | C35: Ashanti Region | D35: Kumasi | E35: Adum · 0205089889
A36: Methodist Medical Centre Tafo | B36: Health Facility | C36: Ashanti Region | D36: Kumasi | E36: Tafo · 0243055193
A37: Methodist Medical Centre Bebu | B37: Health Facility | C37: Ashanti Region | D37: Kumasi | E37: Bebu · 0245497204
... A51: Methodist Medical Centre Kyekyewere | B51: Health Facility | C51: Bono Region | D51: Sunyani | E51: Tain · 0208344780

Sheet Lookups
A1: Institutions | B1: Branches | C1: Engagement Types | D1: Outcomes | E1: Status | F1: Institution Types | G1: Priority
A2: Methodist Church Ghana — Accra Diocese | B2: Accra Main | C2: Courtesy Visit | D2: Prospect Identified | E2: Open | F2: Diocese HQ | G2: High
A3: Methodist Church Ghana — Cape Coast Diocese | B3: Tema | C3: Formal Meeting | D3: Information Gathered | E3: In Progress | F3: Circuit | G3: Medium
A4: Methodist Church Ghana — Effiduase Diocese | B4: Kumasi | C4: Presentation | D4: Quotation Requested | E4: Won | F4: Society/Church | G4: Low
A5: Methodist Church Ghana — Foso Diocese | B5: Obuasi | C5: Quotation Discussion | D5: Quotation Sent | E5: Lost | F5: Health Facility
A6: Methodist Church Ghana — Goaso Diocese | B6: Takoradi | C6: Renewal Visit | D6: Proposal Under Review | E6: Closed | F6: School/Educational
A7: Methodist Church Ghana — Ho Diocese | B7: Tarkwa | C7: Claims Visit | D7: Won — Policy Issued | E7: On Hold | F7: Other Methodist Institution
A8: Methodist Church Ghana — Koforidua Diocese | B8: Cape Coast | C8: Training/Workshop | D8: Lost — Price
A9: Methodist Church Ghana — Kumasi Diocese | B9: Koforidua | C9: Synod Event | D9: Lost — Competitor
A10: Methodist Health Training Institute Afosu Campus | B10: Sunyani | C10: Diocesan Event | D10: Lost — No Decision
A11: Methodist Hospital Aburaso | B11: Techiman | C11: Society Visit | D11: Follow-up Required
A12: Methodist Hospital Ankase | B12: Tamale | C12: Cold Call | D12: Closed — No Interest
A13: Methodist Hospital Wenchi | B13: Ho | C13: Phone Follow-up
A14: Methodist Medical Centre Adagyaman | B14: Wa | C14: Email Follow-up
A15: Methodist Medical Centre Adjoafua | C15: Cross-sell Visit
A16: Methodist Medical Centre Adum | C16: Service Recovery
A17: Methodist Medical Centre Apagya
A18: Methodist Medical Centre Asuakwa
A19: Methodist Medical Centre Bebu
A20: Methodist Medical Centre Benyin/Nzulezu
A21: Methodist Medical Centre Brodekwano
A22: Methodist Medical Centre Gwira Esiem
A23: Methodist Medical Centre Hweehwee
A24: Methodist Medical Centre Kwakuyanya
A25: Methodist Medical Centre Kwawu
A26: Methodist Medical Centre Kyekyewere
A27: Methodist Medical Centre Lake
A28: Methodist Medical Centre Lawra
... A48: Methodist Church Ghana — Winneba Diocese
